<?xml version="1.0" encoding="UTF-8"?>
<sdf version='1.9'>
  <model name='rope'>
    <enable_wind>true</enable_wind>
    <static>false</static>
    <link name='begin_link'>
      <pose>0 0 0 0 0 0</pose>
      <inertial>
        <mass>0.001</mass>
        <inertia>
          <ixx>4.000000000000001e-08</ixx>
          <iyy>4.000000000000001e-08</iyy>
          <izz>4.000000000000001e-08</izz>
        </inertia>
      </inertial>
       <collision name='begin_link_collision'>
        <geometry>
          <sphere>
            <radius>0.01</radius>
          </sphere>
        </geometry>
      </collision> 
      <visual name='begin_link_visual'>
        <geometry>
          <sphere>
            <radius>0.01</radius>
          </sphere>
        </geometry>
      </visual>
    </link>
    <link name='link_0'>
      <pose>0.1 0 0 0 1.570796326794896558 0</pose>
      <inertial>
        <mass>0.001</mass>
        <inertia>
          <ixx>0.0003358333333333334</ixx>
          <iyy>0.0003358333333333334</iyy>
          <izz>5e-06</izz>
        </inertia>
      </inertial>
       <collision name='link_0_collision'>
        <geometry>
          <cylinder>
            <length>0.2</length>
            <radius>0.01</radius>
          </cylinder>
        </geometry>
      </collision> 
      <visual name='link_0_vis'>
        <geometry>
          <cylinder>
            <length>0.2</length>
            <radius>0.01</radius>
          </cylinder>
        </geometry>
        <material>
          <ambient>0 1 0 1</ambient> <!-- green -->
          <diffuse>0 1 0 1</diffuse>
          <specular>0 1 0 1</specular>
        </material>
      </visual>
      <velocity_decay>
        <linear>0.1</linear>
        <angular>0.1</angular>
      </velocity_decay>
      
    </link>
    <joint name='begin_joint_2' type='universal'>
      <pose relative_to='begin_link'/>
      <child>link_0</child>
      <parent>begin_link</parent>
      <axis>
        <xyz>1 0 0</xyz>
      </axis>
      <axis2>
        <xyz>0 1 0</xyz>
      </axis2>
    </joint>
    
    <link name='link_1'>
      <pose>0.30000000000000004 0 0 0 1.570796326794896558 0</pose>
      <inertial>
        <mass>0.001</mass>
        <inertia>
          <ixx>0.0003358333333333334</ixx>
          <iyy>0.0003358333333333334</iyy>
          <izz>5e-06</izz>
        </inertia>
      </inertial>
       <collision name='link_1_collision'>
        <geometry>
          <cylinder>
            <length>0.2</length>
            <radius>0.01</radius>
          </cylinder>
        </geometry>
      </collision> 
      <visual name='link_1_vis'>
        <geometry>
          <cylinder>
            <length>0.2</length>
            <radius>0.01</radius>
          </cylinder>
        </geometry>
        <material>
          <ambient>0 1 0 1</ambient> <!-- green -->
          <diffuse>0 1 0 1</diffuse>
          <specular>0 1 0 1</specular>
        </material>
      </visual>
      <velocity_decay>
        <linear>0.1</linear>
        <angular>0.1</angular>
      </velocity_decay>
      
    </link>
    <joint name='joint_1_2' type='universal'>
      <pose relative_to='link_0'>0 0 0.1 0 0 0</pose>
      <child>link_1</child>
      <parent>link_0</parent>
      <axis>
        <xyz expressed_in='link_0'>1 0 0</xyz>
        <limit>
          <lower>-3.141592653589793</lower>
          <upper>3.141592653589793</upper>
          <effort>100</effort>
          <velocity>10</velocity>
        </limit>
        <dynamics>
          <damping>0.1</damping>
        </dynamics>
      </axis>
      <axis2>
        <xyz expressed_in='link_0'>0 1 0</xyz>
        <limit>
          <lower>-3.141592653589793</lower>
          <upper>3.141592653589793</upper>
          <effort>100</effort>
          <velocity>10</velocity>
        </limit>
        <dynamics>
          <damping>0.1</damping>
        </dynamics>
      </axis2>
    </joint>
    <link name='link_2'>
      <pose>0.5 0 0 0 1.570796326794896558 0</pose>
      <inertial>
        <mass>0.001</mass>
        <inertia>
          <ixx>0.0003358333333333334</ixx>
          <iyy>0.0003358333333333334</iyy>
          <izz>5e-06</izz>
        </inertia>
      </inertial>
       <collision name='link_2_collision'>
        <geometry>
          <cylinder>
            <length>0.2</length>
            <radius>0.01</radius>
          </cylinder>
        </geometry>
      </collision> 
      <visual name='link_2_vis'>
        <geometry>
          <cylinder>
            <length>0.2</length>
            <radius>0.01</radius>
          </cylinder>
        </geometry>
        <material>
          <ambient>0 1 0 1</ambient> <!-- green -->
          <diffuse>0 1 0 1</diffuse>
          <specular>0 1 0 1</specular>
        </material>
      </visual>
      <velocity_decay>
        <linear>0.1</linear>
        <angular>0.1</angular>
      </velocity_decay>
      
    </link>
    <joint name='joint_2_2' type='universal'>
      <pose relative_to='link_1'>0 0 0.1 0 0 0</pose>
      <child>link_2</child>
      <parent>link_1</parent>
      <axis>
        <xyz expressed_in='link_1'>1 0 0</xyz>
        <limit>
          <lower>-3.141592653589793</lower>
          <upper>3.141592653589793</upper>
          <effort>100</effort>
          <velocity>10</velocity>
        </limit>
        <dynamics>
          <damping>0.1</damping>
        </dynamics>
      </axis>
      <axis2>
        <xyz expressed_in='link_1'>0 1 0</xyz>
        <limit>
          <lower>-3.141592653589793</lower>
          <upper>3.141592653589793</upper>
          <effort>100</effort>
          <velocity>10</velocity>
        </limit>
        <dynamics>
          <damping>0.1</damping>
        </dynamics>
      </axis2>
    </joint>
    <link name='link_3'>
      <pose>0.7000000000000001 0 0 0 1.570796326794896558 0</pose>
      <inertial>
        <mass>0.001</mass>
        <inertia>
          <ixx>0.0003358333333333334</ixx>
          <iyy>0.0003358333333333334</iyy>
          <izz>5e-06</izz>
        </inertia>
      </inertial>
       <collision name='link_3_collision'>
        <geometry>
          <cylinder>
            <length>0.2</length>
            <radius>0.01</radius>
          </cylinder>
        </geometry>
      </collision> 
      <visual name='link_3_vis'>
        <geometry>
          <cylinder>
            <length>0.2</length>
            <radius>0.01</radius>
          </cylinder>
        </geometry>
        <material>
          <ambient>0 1 0 1</ambient> <!-- green -->
          <diffuse>0 1 0 1</diffuse>
          <specular>0 1 0 1</specular>
        </material>
      </visual>
      <velocity_decay>
        <linear>0.1</linear>
        <angular>0.1</angular>
      </velocity_decay>
      
    </link>
    <joint name='joint_3_2' type='universal'>
      <pose relative_to='link_2'>0 0 0.1 0 0 0</pose>
      <child>link_3</child>
      <parent>link_2</parent>
      <axis>
        <xyz expressed_in='link_2'>1 0 0</xyz>
        <limit>
          <lower>-3.141592653589793</lower>
          <upper>3.141592653589793</upper>
          <effort>100</effort>
          <velocity>10</velocity>
        </limit>
        <dynamics>
          <damping>0.1</damping>
        </dynamics>
      </axis>
      <axis2>
        <xyz expressed_in='link_2'>0 1 0</xyz>
        <limit>
          <lower>-3.141592653589793</lower>
          <upper>3.141592653589793</upper>
          <effort>100</effort>
          <velocity>10</velocity>
        </limit>
        <dynamics>
          <damping>0.1</damping>
        </dynamics>
      </axis2>
    </joint>
    <link name='link_4'>
      <pose>0.9 0 0 0 1.570796326794896558 0</pose>
      <inertial>
        <mass>0.001</mass>
        <inertia>
          <ixx>0.0003358333333333334</ixx>
          <iyy>0.0003358333333333334</iyy>
          <izz>5e-06</izz>
        </inertia>
      </inertial>
       <collision name='link_4_collision'>
        <geometry>
          <cylinder>
            <length>0.2</length>
            <radius>0.01</radius>
          </cylinder>
        </geometry>
      </collision> 
      <visual name='link_4_vis'>
        <geometry>
          <cylinder>
            <length>0.2</length>
            <radius>0.01</radius>
          </cylinder>
        </geometry>
        <material>
          <ambient>0 1 0 1</ambient> <!-- green -->
          <diffuse>0 1 0 1</diffuse>
          <specular>0 1 0 1</specular>
        </material>
      </visual>
      <velocity_decay>
        <linear>0.1</linear>
        <angular>0.1</angular>
      </velocity_decay>
      
    </link>
    <joint name='joint_4_2' type='universal'>
      <pose relative_to='link_3'>0 0 0.1 0 0 0</pose>
      <child>link_4</child>
      <parent>link_3</parent>
      <axis>
        <xyz expressed_in='link_3'>1 0 0</xyz>
        <limit>
          <lower>-3.141592653589793</lower>
          <upper>3.141592653589793</upper>
          <effort>100</effort>
          <velocity>10</velocity>
        </limit>
        <dynamics>
          <damping>0.1</damping>
        </dynamics>
      </axis>
      <axis2>
        <xyz expressed_in='link_3'>0 1 0</xyz>
        <limit>
          <lower>-3.141592653589793</lower>
          <upper>3.141592653589793</upper>
          <effort>100</effort>
          <velocity>10</velocity>
        </limit>
        <dynamics>
          <damping>0.1</damping>
        </dynamics>
      </axis2>
    </joint>
    <link name='link_5'>
      <pose>1.1 0 0 0 1.570796326794896558 0</pose>
      <inertial>
        <mass>0.001</mass>
        <inertia>
          <ixx>0.0003358333333333334</ixx>
          <iyy>0.0003358333333333334</iyy>
          <izz>5e-06</izz>
        </inertia>
      </inertial>
       <collision name='link_5_collision'>
        <geometry>
          <cylinder>
            <length>0.2</length>
            <radius>0.01</radius>
          </cylinder>
        </geometry>
      </collision> 
      <visual name='link_5_vis'>
        <geometry>
          <cylinder>
            <length>0.2</length>
            <radius>0.01</radius>
          </cylinder>
        </geometry>
        <material>
          <ambient>0 1 0 1</ambient> <!-- green -->
          <diffuse>0 1 0 1</diffuse>
          <specular>0 1 0 1</specular>
        </material>
      </visual>
      <velocity_decay>
        <linear>0.1</linear>
        <angular>0.1</angular>
      </velocity_decay>
      
      <sensor name="imu_sensor" type="imu">
        <always_on>1</always_on>
        <update_rate>250</update_rate>
        <visualize>true</visualize>
      </sensor>
    </link>
    <joint name='joint_5_2' type='universal'>
      <pose relative_to='link_4'>0 0 0.1 0 0 0</pose>
      <child>link_5</child>
      <parent>link_4</parent>
      <axis>
        <xyz expressed_in='link_4'>1 0 0</xyz>
        <limit>
          <lower>-3.141592653589793</lower>
          <upper>3.141592653589793</upper>
          <effort>100</effort>
          <velocity>10</velocity>
        </limit>
        <dynamics>
          <damping>0.1</damping>
        </dynamics>
      </axis>
      <axis2>
        <xyz expressed_in='link_4'>0 1 0</xyz>
        <limit>
          <lower>-3.141592653589793</lower>
          <upper>3.141592653589793</upper>
          <effort>100</effort>
          <velocity>10</velocity>
        </limit>
        <dynamics>
          <damping>0.1</damping>
        </dynamics>
      </axis2>
    </joint>
    <link name='link_6'>
      <pose>1.3000000000000003 0 0 0 1.570796326794896558 0</pose>
      <inertial>
        <mass>0.001</mass>
        <inertia>
          <ixx>0.0003358333333333334</ixx>
          <iyy>0.0003358333333333334</iyy>
          <izz>5e-06</izz>
        </inertia>
      </inertial>
       <collision name='link_6_collision'>
        <geometry>
          <cylinder>
            <length>0.2</length>
            <radius>0.01</radius>
          </cylinder>
        </geometry>
      </collision> 
      <visual name='link_6_vis'>
        <geometry>
          <cylinder>
            <length>0.2</length>
            <radius>0.01</radius>
          </cylinder>
        </geometry>
        <material>
          <ambient>0 1 0 1</ambient> <!-- green -->
          <diffuse>0 1 0 1</diffuse>
          <specular>0 1 0 1</specular>
        </material>
      </visual>
      <velocity_decay>
        <linear>0.1</linear>
        <angular>0.1</angular>
      </velocity_decay>
      
    </link>
    <joint name='joint_6_2' type='universal'>
      <pose relative_to='link_5'>0 0 0.1 0 0 0</pose>
      <child>link_6</child>
      <parent>link_5</parent>
      <axis>
        <xyz expressed_in='link_5'>1 0 0</xyz>
        <limit>
          <lower>-3.141592653589793</lower>
          <upper>3.141592653589793</upper>
          <effort>100</effort>
          <velocity>10</velocity>
        </limit>
        <dynamics>
          <damping>0.1</damping>
        </dynamics>
      </axis>
      <axis2>
        <xyz expressed_in='link_5'>0 1 0</xyz>
        <limit>
          <lower>-3.141592653589793</lower>
          <upper>3.141592653589793</upper>
          <effort>100</effort>
          <velocity>10</velocity>
        </limit>
        <dynamics>
          <damping>0.1</damping>
        </dynamics>
      </axis2>
    </joint>
    <link name='link_7'>
      <pose>1.5000000000000002 0 0 0 1.570796326794896558 0</pose>
      <inertial>
        <mass>0.001</mass>
        <inertia>
          <ixx>0.0003358333333333334</ixx>
          <iyy>0.0003358333333333334</iyy>
          <izz>5e-06</izz>
        </inertia>
      </inertial>
       <collision name='link_7_collision'>
        <geometry>
          <cylinder>
            <length>0.2</length>
            <radius>0.01</radius>
          </cylinder>
        </geometry>
      </collision> 
      <visual name='link_7_vis'>
        <geometry>
          <cylinder>
            <length>0.2</length>
            <radius>0.01</radius>
          </cylinder>
        </geometry>
        <material>
          <ambient>0 1 0 1</ambient> <!-- green -->
          <diffuse>0 1 0 1</diffuse>
          <specular>0 1 0 1</specular>
        </material>
      </visual>
      <velocity_decay>
        <linear>0.1</linear>
        <angular>0.1</angular>
      </velocity_decay>
      
    </link>
    <joint name='joint_7_2' type='universal'>
      <pose relative_to='link_6'>0 0 0.1 0 0 0</pose>
      <child>link_7</child>
      <parent>link_6</parent>
      <axis>
        <xyz expressed_in='link_6'>1 0 0</xyz>
        <limit>
          <lower>-3.141592653589793</lower>
          <upper>3.141592653589793</upper>
          <effort>100</effort>
          <velocity>10</velocity>
        </limit>
        <dynamics>
          <damping>0.1</damping>
        </dynamics>
      </axis>
      <axis2>
        <xyz expressed_in='link_6'>0 1 0</xyz>
        <limit>
          <lower>-3.141592653589793</lower>
          <upper>3.141592653589793</upper>
          <effort>100</effort>
          <velocity>10</velocity>
        </limit>
        <dynamics>
          <damping>0.1</damping>
        </dynamics>
      </axis2>
    </joint>
    <link name='link_8'>
      <pose>1.7000000000000002 0 0 0 1.570796326794896558 0</pose>
      <inertial>
        <mass>0.001</mass>
        <inertia>
          <ixx>0.0003358333333333334</ixx>
          <iyy>0.0003358333333333334</iyy>
          <izz>5e-06</izz>
        </inertia>
      </inertial>
       <collision name='link_8_collision'>
        <geometry>
          <cylinder>
            <length>0.2</length>
            <radius>0.01</radius>
          </cylinder>
        </geometry>
      </collision> 
      <visual name='link_8_vis'>
        <geometry>
          <cylinder>
            <length>0.2</length>
            <radius>0.01</radius>
          </cylinder>
        </geometry>
        <material>
          <ambient>0 1 0 1</ambient> <!-- green -->
          <diffuse>0 1 0 1</diffuse>
          <specular>0 1 0 1</specular>
        </material>
      </visual>
      <velocity_decay>
        <linear>0.1</linear>
        <angular>0.1</angular>
      </velocity_decay>
      
    </link>
    <joint name='joint_8_2' type='universal'>
      <pose relative_to='link_7'>0 0 0.1 0 0 0</pose>
      <child>link_8</child>
      <parent>link_7</parent>
      <axis>
        <xyz expressed_in='link_7'>1 0 0</xyz>
        <limit>
          <lower>-3.141592653589793</lower>
          <upper>3.141592653589793</upper>
          <effort>100</effort>
          <velocity>10</velocity>
        </limit>
        <dynamics>
          <damping>0.1</damping>
        </dynamics>
      </axis>
      <axis2>
        <xyz expressed_in='link_7'>0 1 0</xyz>
        <limit>
          <lower>-3.141592653589793</lower>
          <upper>3.141592653589793</upper>
          <effort>100</effort>
          <velocity>10</velocity>
        </limit>
        <dynamics>
          <damping>0.1</damping>
        </dynamics>
      </axis2>
    </joint>
    <link name='link_9'>
      <pose>1.9000000000000001 0 0 0 1.570796326794896558 0</pose>
      <inertial>
        <mass>0.001</mass>
        <inertia>
          <ixx>0.0003358333333333334</ixx>
          <iyy>0.0003358333333333334</iyy>
          <izz>5e-06</izz>
        </inertia>
      </inertial>
       <collision name='link_9_collision'>
        <geometry>
          <cylinder>
            <length>0.2</length>
            <radius>0.01</radius>
          </cylinder>
        </geometry>
      </collision> 
      <visual name='link_9_vis'>
        <geometry>
          <cylinder>
            <length>0.2</length>
            <radius>0.01</radius>
          </cylinder>
        </geometry>
        <material>
          <ambient>0 1 0 1</ambient> <!-- green -->
          <diffuse>0 1 0 1</diffuse>
          <specular>0 1 0 1</specular>
        </material>
      </visual>
      <velocity_decay>
        <linear>0.1</linear>
        <angular>0.1</angular>
      </velocity_decay>
      
    </link>
    <joint name='joint_9_2' type='universal'>
      <pose relative_to='link_8'>0 0 0.1 0 0 0</pose>
      <child>link_9</child>
      <parent>link_8</parent>
      <axis>
        <xyz expressed_in='link_8'>1 0 0</xyz>
        <limit>
          <lower>-3.141592653589793</lower>
          <upper>3.141592653589793</upper>
          <effort>100</effort>
          <velocity>10</velocity>
        </limit>
        <dynamics>
          <damping>0.1</damping>
        </dynamics>
      </axis>
      <axis2>
        <xyz expressed_in='link_8'>0 1 0</xyz>
        <limit>
          <lower>-3.141592653589793</lower>
          <upper>3.141592653589793</upper>
          <effort>100</effort>
          <velocity>10</velocity>
        </limit>
        <dynamics>
          <damping>0.1</damping>
        </dynamics>
      </axis2>
    </joint>
    <link name='end_link'>
      <pose>2 0 0 0 0 0</pose>
      <inertial>
        <mass>0.001</mass>
        <inertia>
          <ixx>4.000000000000001e-08</ixx>
          <iyy>4.000000000000001e-08</iyy>
          <izz>4.000000000000001e-08</izz>
        </inertia>
      </inertial>
       <collision name='end_link_collision'>
        <geometry>
          <sphere>
            <radius>0.01</radius>
          </sphere>
        </geometry>
      </collision> 
      <visual name='end_link_visual'>
        <geometry>
          <sphere>
            <radius>0.01</radius>
          </sphere>
        </geometry>
      </visual>
    </link>
    <joint name='joint_end_1' type='universal'>
      <pose relative_to='end_link'/>
      <child>end_link</child>
      <parent>link_9</parent>
      <axis>
        <xyz>0 0 1</xyz>
      </axis>
      <axis2>
        <xyz>0 1 0</xyz>
      </axis2>
    </joint>
  </model>
</sdf>